Workbook
Name try: Plan2!$A$1:$F$352

Sheet Plan1
A1: PEDIDO - CS
A2: DATA : | F2: Nome Fantasia: | AA2: Nª PED
A3: RAZÃO SOCIAL:
A4: ENDEREÇO: | AF4: 15
A5: CIDADE: | O5: Bairro : | AA5: UF: | AF5: 0015E
A6: CEP : | H6: TEL: | Q6: WhatsApp | X6: Contato: | AF6: 80
A7: CNPJ / CPF: | M7: Inscrição Estadual: | U7: E-mail : | AF7: 0080E
A8: COND PGTO | N8: FORMA PGTO | U8: Data da Entrega: | AF8: 83
L9: INFANTIL / ADULTO | Q9: PLUS | U9: JUVENIL
A10: TAMANHOS | M10: 2 | N10: 4 | O10: 6 | P10: 8 | U10: 10 | V10: 12 | W10: 14 | X10: 16
L11: PP | M11: P | N11: M | O11: G | P11: GG | Q11: XG | R11: XG2 | S11: XG3 | T11: XG4 | AF11: 0085E
A12: REF | B12: OBSERVAÇÃO | L12: 36 | M12: 38 | N12: 40 | O12: 42 | P12: 44/46 | Q12: 48 | R12: 50 | S12: 52 | T12: 54 | Z12: QUANT | AA12: UNIT | AB12: TOTAL | AF12: 86
Z13: =L13+M13+N13+O13+P13+U13+V13+W13+X13+Q13+R13+S13+T13 -> 0 | AA13: =IFERROR(VLOOKUP(A13,Plan2!$A$1:$F$777,6,0),"-") -> - | AB13: =IFERROR(AA13*Z13,"-") -> - | AF13: 0086E
Z14: =L14+M14+N14+O14+P14+U14+V14+W14+X14+Q14+R14+S14+T14 -> 0 | AA14: =IFERROR(VLOOKUP(A14,Plan2!$A$1:$F$777,6,0),"-") -> - | AB14: =IFERROR(AA14*Z14,"-") -> - | AF14: 87
Z15: =L15+M15+N15+O15+P15+U15+V15+W15+X15+Q15+R15+S15+T15 -> 0 | AA15: =IFERROR(VLOOKUP(A15,Plan2!$A$1:$F$777,6,0),"-") -> - | AB15: =IFERROR(AA15*Z15,"-") -> - | AF15: 0087E
Z16: =L16+M16+N16+O16+P16+U16+V16+W16+X16+Q16+R16+S16+T16 -> 0 | AA16: =IFERROR(VLOOKUP(A16,Plan2!$A$1:$F$777,6,0),"-") -> - | AB16: =IFERROR(AA16*Z16,"-") -> - | AF16: 88
Z17: =L17+M17+N17+O17+P17+U17+V17+W17+X17+Q17+R17+S17+T17 -> 0 | AA17: =IFERROR(VLOOKUP(A17,Plan2!$A$1:$F$777,6,0),"-") -> - | AB17: =IFERROR(AA17*Z17,"-") -> - | AF17: 0088E
Z18: =L18+M18+N18+O18+P18+U18+V18+W18+X18+Q18+R18+S18+T18 -> 0 | AA18: =IFERROR(VLOOKUP(A18,Plan2!$A$1:$F$777,6,0),"-") -> - | AB18: =IFERROR(AA18*Z18,"-") -> - | AF18: 90
Z19: =L19+M19+N19+O19+P19+U19+V19+W19+X19+Q19+R19+S19+T19 -> 0 | AA19: =IFERROR(VLOOKUP(A19,Plan2!$A$1:$F$777,6,0),"-") -> - | AB19: =IFERROR(AA19*Z19,"-") -> - | AF19: 0090E
Z20: =L20+M20+N20+O20+P20+U20+V20+W20+X20+Q20+R20+S20+T20 -> 0 | AA20: =IFERROR(VLOOKUP(A20,Plan2!$A$1:$F$777,6,0),"-") -> - | AB20: =IFERROR(AA20*Z20,"-") -> - | AF20: 91
Z21: =L21+M21+N21+O21+P21+U21+V21+W21+X21+Q21+R21+S21+T21 -> 0 | AA21: =IFERROR(VLOOKUP(A21,Plan2!$A$1:$F$777,6,0),"-") -> - | AB21: =IFERROR(AA21*Z21,"-") -> - | AF21: 0091E
Z22: =L22+M22+N22+O22+P22+U22+V22+W22+X22+Q22+R22+S22+T22 -> 0 | AA22: =IFERROR(VLOOKUP(A22,Plan2!$A$1:$F$777,6,0),"-") -> - | AB22: =IFERROR(AA22*Z22,"-") -> - | AF22: 92
Z23: =L23+M23+N23+O23+P23+U23+V23+W23+X23+Q23+R23+S23+T23 -> 0 | AA23: =IFERROR(VLOOKUP(A23,Plan2!$A$1:$F$777,6,0),"-") -> - | AB23: =IFERROR(AA23*Z23,"-") -> - | AF23: 0092E
Z24: =L24+M24+N24+O24+P24+U24+V24+W24+X24+Q24+R24+S24+T24 -> 0 | AA24: =IFERROR(VLOOKUP(A24,Plan2!$A$1:$F$777,6,0),"-") -> - | AB24: =IFERROR(AA24*Z24,"-") -> - | AF24: 93
Z25: =L25+M25+N25+O25+P25+U25+V25+W25+X25+Q25+R25+S25+T25 -> 0 | AA25: =IFERROR(VLOOKUP(A25,Plan2!$A$1:$F$777,6,0),"-") -> - | AB25: =IFERROR(AA25*Z25,"-") -> - | AF25: 0093E
Z26: =L26+M26+N26+O26+P26+U26+V26+W26+X26+Q26+R26+S26+T26 -> 0 | AA26: =IFERROR(VLOOKUP(A26,Plan2!$A$1:$F$777,6,0),"-") -> - | AB26: =IFERROR(AA26*Z26,"-") -> - | AF26: 94
Z27: =L27+M27+N27+O27+P27+U27+V27+W27+X27+Q27+R27+S27+T27 -> 0 | AA27: =IFERROR(VLOOKUP(A27,Plan2!$A$1:$F$777,6,0),"-") -> - | AB27: =IFERROR(AA27*Z27,"-") -> - | AF27: 0094E
Z28: =L28+M28+N28+O28+P28+U28+V28+W28+X28+Q28+R28+S28+T28 -> 0 | AA28: =IFERROR(VLOOKUP(A28,Plan2!$A$1:$F$777,6,0),"-") -> - | AB28: =IFERROR(AA28*Z28,"-") -> - | AF28: 95
Z29: =L29+M29+N29+O29+P29+U29+V29+W29+X29+Q29+R29+S29+T29 -> 0 | AA29: =IFERROR(VLOOKUP(A29,Plan2!$A$1:$F$777,6,0),"-") -> - | AB29: =IFERROR(AA29*Z29,"-") -> - | AF29: 0095E
Z30: =L30+M30+N30+O30+P30+U30+V30+W30+X30+Q30+R30+S30+T30 -> 0 | AA30: =IFERROR(VLOOKUP(A30,Plan2!$A$1:$F$777,6,0),"-") -> - | AB30: =IFERROR(AA30*Z30,"-") -> - | AF30: 96
Z31: =L31+M31+N31+O31+P31+U31+V31+W31+X31+Q31+R31+S31+T31 -> 0 | AA31: =IFERROR(VLOOKUP(A31,Plan2!$A$1:$F$777,6,0),"-") -> - | AB31: =IFERROR(AA31*Z31,"-") -> - | AF31: 0096E
Z32: =L32+M32+N32+O32+P32+U32+V32+W32+X32+Q32+R32+S32+T32 -> 0 | AA32: =IFERROR(VLOOKUP(A32,Plan2!$A$1:$F$777,6,0),"-") -> - | AB32: =IFERROR(AA32*Z32,"-") -> - | AF32: 102
Z33: =L33+M33+N33+O33+P33+U33+V33+W33+X33+Q33+R33+S33+T33 -> 0 | AA33: =IFERROR(VLOOKUP(A33,Plan2!$A$1:$F$777,6,0),"-") -> - | AB33: =IFERROR(AA33*Z33,"-") -> - | AF33: 103
Z34: =L34+M34+N34+O34+P34+U34+V34+W34+X34+Q34+R34+S34+T34 -> 0 | AA34: =IFERROR(VLOOKUP(A34,Plan2!$A$1:$F$777,6,0),"-") -> - | AB34: =IFERROR(AA34*Z34,"-") -> - | AF34: 104
Z35: =L35+M35+N35+O35+P35+U35+V35+W35+X35+Q35+R35+S35+T35 -> 0 | AA35: =IFERROR(VLOOKUP(A35,Plan2!$A$1:$F$777,6,0),"-") -> - | AB35: =IFERROR(AA35*Z35,"-") -> - | AF35: 106
Z36: =L36+M36+N36+O36+P36+U36+V36+W36+X36+Q36+R36+S36+T36 -> 0 | AA36: =IFERROR(VLOOKUP(A36,Plan2!$A$1:$F$777,6,0),"-") -> - | AB36: =IFERROR(AA36*Z36,"-") -> - | AF36: 0106E
Z37: =L37+M37+N37+O37+P37+U37+V37+W37+X37+Q37+R37+S37+T37 -> 0 | AA37: =IFERROR(VLOOKUP(A37,Plan2!$A$1:$F$777,6,0),"-") -> - | AB37: =IFERROR(AA37*Z37,"-") -> - | AF37: 108 | AG37: *PROMOÇÃO*
Z38: =L38+M38+N38+O38+P38+U38+V38+W38+X38+Q38+R38+S38+T38 -> 0 | AA38: =IFERROR(VLOOKUP(A38,Plan2!$A$1:$F$777,6,0),"-") -> - | AB38: =IFERROR(AA38*Z38,"-") -> - | AF38: 109
Z39: =L39+M39+N39+O39+P39+U39+V39+W39+X39+Q39+R39+S39+T39 -> 0 | AA39: =IFERROR(VLOOKUP(A39,Plan2!$A$1:$F$777,6,0),"-") -> - | AB39: =IFERROR(AA39*Z39,"-") -> - | AF39: 0109E
Z40: =L40+M40+N40+O40+P40+U40+V40+W40+X40+Q40+R40+S40+T40 -> 0 | AA40: =IFERROR(VLOOKUP(A40,Plan2!$A$1:$F$777,6,0),"-") -> - | AB40: =IFERROR(AA40*Z40,"-") -> - | AF40: 110
...

Sheet Plan2
A1: 2201 | F1: 69.9 | H1: A VISTA | J1: FRETE
A2: 2201E | F2: 76.9 | H2: CARTÃO | J2: (CIF) Pago p/ Fábrica
A3: 2202 | F3: 59.9
A4: 2203 | F4: 67.9
A5: 2204 | F5: 95
A6: 2204E | F6: 99.9
A7: 2205 | F7: 74.9 | H7: CHEQUE | I7: COND DE PAGAMENTO | J7: (FOB) Pago p/ Cliente
A8: 2205E | F8: 82.5 | H8: BOLETO | I8: A VISTA
A9: 2206 | F9: 83.9 | I9: 15/30
A10: 2207 | F10: 57.9 | I10: 30/60
A11: 2207E | F11: 63.9 | I11: 30/60/90/120
A12: 2208 | F12: 58.9 | I12: 20
A13: 2208E | F13: 64.9 | I13: 10
A14: 2212 | F14: 52.5 | I14: 28
A15: 2213 | F15: 59.9 | I15: 15/30
A16: 2213E | F16: 65.9 | I16: 30/60/90/120
A17: 2215 | F17: 70.9 | I17: 15/30/45
A18: 2215E | F18: 78.5 | I18: 30/45/60
A19: 2216 | F19: 65.9 | I19: 45
A20: 2216E | F20: 72.5 | I20: Personalizada:
A21: 2217 | F21: 65.9
A22: 2217E | F22: 72.5
A23: 2230 | F23: 76.9
A24: 2230E | F24: 84.9
A25: 2232 | F25: 62.9
A26: 2232E | F26: 69.5
A27: 2234 | F27: 82.9
A28: 2234E | F28: 87.5
A29: 2240 | F29: 76.9
A30: 2240E | F30: 80.9
A31: 2244 | F31: 65.9
A32: 2244E | F32: 72.5
A33: 2246 | F33: 53.9
A34: 2246E | F34: 59.5
A35: 2247 | F35: 39.9
A36: 2251 | F36: 32.9
A37: 2252 | F37: 32.9
A38: 2253 | B38: *PROMOÇÃO* | F38: 49.9
A39: 2254 | F39: 49.9
A40: 2254E | F40: 54.9
...
